Workbook

Sheet Orientações
A7: Aba: Identificação do projeto | I7: Aba: Estrutura de quebra de trabalho do projeto (EAP)
A8: Cabeçalho: Preencher com os dados referentes ao projeto Equipe do projeto: Preencher com o nome dos membros que trabalharão no projeto Situação atual, Stakeholders e Justificativa do projeto: Escrita livre com uma breve descrição dos motivos que tornam o projeto relevante. Importante destacar se ja existir alguma iniciativa institucional, quem são os setores internos e externos que podem ser beneficiados ou afetados pelo projeto e também o que se espera de positivo ao final do projeto. Objetivos do Projeto: O objetivo geral deve apontar qual a principal finalidade do projeto. Sugere-se que seja iniciado com um verbo no infinitivo. Os objetivos específicos são os desdobramentos do objetivo principal. Representam o "como", as etapas que serão cumpridas para o atingimento do objetivo geral. Perguntas que ajudam a formular o objetivo especifico, por exemplo: Qual a situação real que queremos ver após o término do projeto? Qual a mudança especifica que o projeto pretende alcançar? Os objetvos complementares são entregas e ações relevantes, mas que se não cumpridas, não inviabilizam o cumprimento do objetivo principal. Riscos do Projeto (opcional): Registrar os principais eventos ou condições incertas que, se ocorrerem, poderão afetar de forma positiva ou negativa o andamento do projeto. O preenchimento deve considerar tanto riscos internos (recursos, prazos, comunicação, dependências) quanto externos (fornecedores, parceiros, mudanças institucionais ou ambientais). | I8: Cabeçalho: Preenchido automaticamente Estrutura de quebra de trabalho do projeto: Subdivisão das entregas e do trabalho do projeto em componentes menores e mais facilmente gerenciáveis. Pode ser confeccionado diretamente na planilha ou confeccionar em outro programa e inserir a imagem da EAP na aba da planilha. Artigos sobre como elaborar uma EAP: https://escritoriodeprojetos.com.br/eap/; https://repositorio.enap.gov.br/bitstream/1/1107/1/GerenciaDeProjeos_modulo_5_final_.pdf Vídeos sobre como elaborar uma EAP: https://www.youtube.com/watch?v=WcNE8p4R0-g; https://www.youtube.com/watch?v=Cpffygavkx4 *Os artigos e vídeos contém exemplos de EAP
A28: Aba: Entregas e Custos Previstos | I28: Aba: Cronograma
A29: Cabeçalho: Preenchido automaticamente Entregas previstas: Principal entrega: Devem apresentar, de forma clara a PRINCIPAL ENTREGA do projeto (aquela que for considerada a mais relevante/que trará maiores benefícios). Entregas complementares: Apresentar as outras entregas previstas para o projeto, que complementam a entrega principal. Cada linha deve ser preenchida com uma das entregas parciais do projeto. A Estrutura de Quebra de Trabalho do projeto pode ser um ponto de partida para a definição das entregas previstas. Custos Variáveis: Há três opções para o status de custo: "Sem custos" - os únicos custos são mão de obra do CBMMG e utilização de equipamentos já disponíveis na corporação "Captado" - estão previstos custos que já se encontram à disposição do projeto, seja via captação, doação ou orçamento direto do CBMMG; "Não captado" - para a realização do projeto existem custos que ainda não estão à disposição do projeto, sendo necessário realizar a captação destes. | I29: Cabeçalho: Preenchido automaticamente Cronograma: A tabela do cronograma é dividida em 6 colunas. Com exceção da coluna "Status", as demais deverão ser preenchidas no início (abertura do projeto). A coluna "Status" será preenchida durante as reuniões de monitoramento do projeto. Atividades - Refere-se às divisões metodológicas do percurso do projeto. As principais entregas previstas e a EAP podem servir de orientação para a elaboração das atividades. Equivale à coluna "O Quê" em um plano de ação 5W2H. - Identifique e insira na planilha todas as etapas antes de passar para a próxima coluna. Previsão de conclusão - A data prevista para a finalização da atividade proposta. É o prazo limite da tarefa. Percentual correspondente do projeto - Neste momento será necessário dimensionar o esforço para cumprir cada etapa. Essa coluna reflete a carga de trabalho de uma atividade em relação ao trabalho total. A soma de todas as atividades deverá ser igual a 100%. Responsável e Observações - Colunas opcionais, que auxiliam o gerente de projeto a delegar e controlar a execução das atividades do projeto Essa aba irá orientar o monitoramento e acompanhamento do projeto. Material sobre como elaborar um cronograma: https://www.youtube.com/watch?v=1geI5bmv_8A https://artia.com/blog/cronograma-de-projetos/ https://www.lucidchart.com/blog/pt/8-passos-para-criar-um-cronograma-de-gerenciamento-de-projetos https://monday.com/blog/pt/gestao-de-projetos-pt/cronograma-de-projeto-a-maneira-mais-simples-de-criar-um/
A57: Aba: Monitoramento | I57: Aba: Termo de Encerramento
A58: Cabeçalho: Preenchido automaticamente Gráfico Real x Planejado: Preenchido automaticamente durante o monitoramento - indicador objetivo Indicador de evolução do projeto: Preenchido automaticamente durante o monitoramento - indicador objetivo Progresso do projeto: Preenchido automaticamente durante o monitoramento - indicador objetivo Atas das reuniões de monitoramento: Serão preenchidas juntamente com a DAI durante as reuniões de monitoramento. Trata-se de um breve resumo sobre o andamento do projeto no período compreendido entre a última reunião e aquele momento. Serve como indicador subjetivo do progresso do projeto e como memória para acompanhamento do gerente do portfólio. Situação atual do projeto: Preenchido automaticamento com a ata da última reunião realizada | I58: Cabeçalho: Preenchido automaticamente Objetivo do Projeto: Preenchido automaticamente da aba "Identificação do proejeto" Metas e Entregas Previstas: Preenchido automaticamente a partir da aba “Metas e Entregas Previstas”. Adaptações no Escopo Inicial do Projeto: Registrar qualquer modificação significativa em relação ao planejamento original. Exemplo: inclusão ou exclusão de entregas, alteração de prazos ou de recursos. Status do Projeto: Selecionar a situação final do projeto: concluído; não concluído ou cancelado. Utilizar o campo “Observação” para contextualizar o status ou destacar pontos relevantes do encerramento. Produtos: Relacionar a principal entrega e eventuais entregas complementares do projeto, anexando ou referenciando documentos comprobatórios (relatórios, registros fotográficos, certificados, pareceres, etc.). Principais Problemas e Entraves: Descrever as dificuldades enfrentadas durante a execução (ex.: limitações de recursos, comunicação, prazos, parcerias) e o impacto causado no desenvolvimento das atividades. Continuidade: Listar as tarefas, metas ou atividades não concluídas, indicando o planejamento para conclusão e o tempo estimado. Essa informação facilita o acompanhamento pela equipe de portfólio ou pelo gerente de eixo no ciclo seguinte. Considerações do Gerente do Projeto – Lições Aprendidas: Registrar as principais experiências positivas e negativas, destacando recomendações para futuros projetos. Observações: Espaço livre para observações adicionais do gerente do projeto, como sugestões de melhoria, registros complementares ou menções de reconhecimento à equipe envolvida.

Sheet Cronograma Geral e Referências
A7: CRONOGRAMA PORTFÓLIO DA 6ª EDIÇÃO DO PLANO DE COMANDO
A8: Data de Referência | B8: Monitoramento Mensal [AEST e Gerentes de Projeto] | C8: Monitoramento Bimestral [Gerente de Portfólio e de Eixo] | D8: Finalidade do Monitoramento
B9: - | C9: - | D9: Formalizações, capacitações e ajustes Plano de Gerenciamento
B10: - | C10: - | D10: Formalizações, capacitações e ajustes Plano de Gerenciamento
B11: 1º monitoramento | C11: - | D11: Acompanhamento das entregas, ajuste das rota e ritmo de trabalho
B12: 2º monitoramento | C12: 1ªReunião de Monitoramento Bimestral - CHEM | D12: Acompanhamento das entregas, ajuste das rota e ritmo de trabalho, com apresentação dos Gerentes de Eixo para o Gerente de Portfólio.
B13: 3º monitoramento | C13: - | D13: Acompanhamento das entregas, ajuste das rota e ritmo de trabalho
B14: 4º monitoramento | C14: 2ªReunião de Monitoramento Bimestral - CHEM | D14: Acompanhamento das entregas, ajuste das rota e ritmo de trabalho, com apresentação dos Gerentes de Eixo para o Gerente de Portfólio.
B15: 5º monitoramento | C15: - | D15: Acompanhamento das entregas, ajuste das rota e ritmo de trabalho
B16: 6º monitoramento | C16: 3ªReunião de Monitoramento Bimestral - CHEM | D16: Acompanhamento das entregas, ajuste das rota e ritmo de trabalho, com apresentação dos Gerentes de Eixo para o Gerente de Portfólio.
B17: 7º monitoramento | C17: - | D17: Acompanhamento das entregas, ajuste das rota e ritmo de trabalho
B18: 8º monitoramento | C18: 4ªReunião de Monitoramento Bimestral - CHEM | D18: Acompanhamento das entregas, ajuste das rota e ritmo de trabalho, com apresentação dos Gerentes de Eixo para o Gerente de Portfólio.
B19: 9º monitoramento | C19: - | D19: Acompanhamento das entregas, ajuste das rota e ritmo de trabalho
B20: 10º monitoramento | C20: 5ªReunião de Monitoramento Bimestral - CHEM | D20: Acompanhamento das entregas, ajuste das rota e ritmo de trabalho, com apresentação dos Gerentes de Eixo para o Gerente de Portfólio.
... B23: 12º monitoramento | C23: 6ªReunião de Monitoramento Bimestral - CHEM | D23: Encerramento do ciclo e consolidação dos resultados
B24: - | D24: Envio do Termo de Encerramento do Projeto
A27: DOCUMENTAÇÃO DE REFERÊNCIA
A28: ORDEM | B28: Referência
A29: 1 | B29: 6ª Edição do Plano de Comando
A30: 2 | B30: Diretriz nº 06
A31: 3
A32: 4
A33: 5
A34: 6
A35: 7
A36: 8
A37: 9
A38: 10

Sheet Identificação do projeto
B9: Gerente do portfólio: | C9: Coronel BM Moisés Magalhães de Sousa | H9: Programa: | J9: Aperfeiçoamento Tecnológico do CBMMG
B10: Eixo: | C10: Inovação e Transformação Digital | H10: Projeto: | J10: Modernização dos Sistema de Informação do CBMMG - GT's Integrados
H11: Subprojeto: | J11: Base Integrada de Segurança Pública - BISP
B12: Gerente de Eixo: | C12: Coronel BM Luiz Frederico Barreto Pascoal | H12: Gerente de Projeto: | J12: Tenente-coronel BM Paulo Afonso Montezano Crispim
Q14: 0
A15: Situação atual, Stakolders e Justificativa do projeto:
A16: SITUAÇÃO ATUAL A Base Integrada de Segurança Pública (BISP) é o data lake corporativo dos sistemas das Forças de Segurança Pública (SISP), operado pela SEJUSP por meio da PRODEMGE. O CBMMG já possui integrados à BISP os dados do CAD, do CAD ESCALA (ainda utilizado pela AAS), do REDS e do Módulo de Licenciamento do Infoscip. O Módulo de Fiscalização do Infoscip foi integrado na Sprint 56 (entrega em 07/11/2025), com criação das views para a DAT. A etapa seguinte — inclusão dos dados de Recursos Humanos (SIGP), abrangendo os 17 universos de RH — encontra-se paralisada por depender da aquisição de ferramenta de terceiros (IBM "DVM") capaz de ler os dados diretamente do Mainframe, sem importação via FTP, com previsão de aquisição para março/2026 e possível custo a ser rateado ao CBMMG. STAKEHOLDERS Internos: SDTS, DAT, DRH, CINSP, EMBM/2 e AAS. Externos: SEJUSP (Observatório / Superintendência de Integração da Segurança Pública), PRODEMGE, PMMG e PCMG. JUSTIFICATIVA A consolidação dos dados do CBMMG em ambiente corporativo e seguro viabiliza o uso de inteligência de dados (painéis, indicadores e relatórios) e a tomada de decisão baseada em evidências. A integração do Infoscip Fiscalização é condição indispensável para a manutenção da série histórica do ISCIP, cujo parâmetro "F" passa a ser obtido exclusivamente desse módulo (antes oriundo do REDS). A integração dos dados de RH proporcionará salto qualitativo na gestão de pessoal (dimensionamento de efetivo, saúde ocupacional, controle de licenças e análises preditivas de disponibilidade). O acesso à BISP também permite ao CBMMG desenvolver ferramentas secundárias — como os painéis de monitoramento utilizados no período de fortes chuvas em Juiz de Fora —, agregando eficiência, economicidade e transparência ao serviço prestado à sociedade mineira.
A25: Time do projeto: | I25: Objetivos do Projeto
A26: Ord | B26: Posto/Graduação | C26: Nome | F26: Unidade | I26: Objetivo Geral Promover a evolução da Base Integrada de Segurança Pública — BISP, por meio da ampliação da integração de dados estratégicos do CBMMG, contemplando a consolidação das informações do Infoscip Fiscalização e a inclusão progressiva dos dados de Recursos Humanos/SIGP, a fim de fortalecer a governança institucional, subsidiar a tomada de decisão baseada em evidências e ampliar a capacidade de análise, planejamento e gestão operacional e administrativa do Corpo de Bombeiros Militar de Minas Gerais. Objetivos Específicos Consolidar a integração das tabelas do Infoscip Fiscalização na BISP, permitindo a utilização dos dados em painéis, relatórios gerenciais, indicadores estratégicos e análises relacionadas à atividade de fiscalização do SSCIP. Viabilizar a manutenção da série histórica do Índice de Segurança Contra Incêndio e Pânico — ISCIP, garantindo que o parâmetro “F” seja alimentado a partir dos registros oficiais do Infoscip Fiscalização. Planejar a inclusão dos dados de Recursos Humanos/SIGP na BISP, contemplando informações como dados pessoais, situação funcional, movimentações, licenças, férias, promoções, cursos, exames e registros disciplinares. Acompanhar, junto à SEJUSP, PRODEMGE e demais atores envolvidos, a definição da solução tecnológica necessária para extração, tratamento e disponibilização dos dados oriundos do Mainframe/SIGP. Disponibilizar dados corporativos de RH em ambiente seguro, estruturado e governado, permitindo cruzamentos, análises preditivas e construção de indicadores sobre efetivo, disponibilidade, movimentação e gestão de pessoal.
A27: 1 | B27: Major | C27: Fabrício Rocha Xavier | F27: SDTS/3
A28: 2 | B28: Capitão | C28: Cleyton | F28: SDTS
A29: 3 | B29: Capitão | C29: Marco Antônio | F29: CINSP
A30: 4 | B30: Capitão | C30: Daniel Simon | F30: DAT
A31: 5 | B31: Major | C31: Fabiano | F31: CINSP
A32: 6 | B32: 1°Tenente | C32: Fortes | F32: DRH
A33: 7
A34: 8
A35: 9
A36: 10
E39: Riscos do Projeto (opcional)
E40: Ord | F40: Risco | H40: Categoria | I40: Probabilidade | J40: Impacto | K40: Severidade | L40: Nivel de Risco | M40: Tratamento | N40: Detalhamento do tratamento | O40: Responsável
E41: 1 | F41: Indefinição da ferramenta de extração dos dados do Mainframe/SIGP | H41: Estratégico | I41: 4 | J41: 5 | K41: 20 | L41: Risco alto | M41: Aceitar o risco | N41: Acompanhar definição da solução técnica junto à SEJUSP/PRODEMGE, incluindo alternativa DVM ou solução equivalente. | O41: SDTS/DRH/BISP
E42: 2 | F42: Custo adicional para aquisição/licenciamento da ferramenta terceira | H42: Estratégico | I42: 3 | J42: 3 | K42: 12 | L42: Risco alto | M42: Aceitar o risco | N42: Avaliar possibilidade de absorção em contrato existente ou planejamento orçamentário específico. | O42: CBMMG/SEJUSP
E43: 3 | F43: Necessidade de reestruturação dos dados de RH antes da ingestão | H43: Estratégico | I43: 3 | J43: 3 | K43: 12 | L43: Risco alto | M43: Aceitar o risco | N43: Realizar levantamento dos universos, regras de negócio, chaves de relacionamento e qualidade dos dados do SIGP. | O43: DRH/PRODEMGE
E44: 4 | F44: Atraso na homologação e disponibilização de views para consumo institucional | H44: Estratégico | I44: 3 | J44: 3 | K44: 9 | L44: Risco moderado | M44: Aceitar o risco | N44: Definir marcos de homologação, responsáveis e critérios mínimos de aceite até o final de 2026. | O44: SDTS/BISP
E45: 5 | F45: Restrições de acesso e governança por conter dados pessoais e funcionais | H45: Estratégico | I45: 3 | J45: 5 | K45: 15 | L45: Risco alto | M45: Aceitar o risco | N45: Definir perfis de acesso, trilhas de auditoria, finalidade de uso e regras de anonimização quando aplicável. | O45: DRH/SDTS/SEJUSP
E46: 6 | K46: =I46*J46 -> 0 | L46: =IF(K46<5,"Risco pequeno",IF(K46<10,"Risco moderado",IF(K46<28,"Risco alto","Risco crítico"))) -> Risco pequeno
E47: 7 | K47: =I47*J47 -> 0 | L47: =IF(K47<5,"Risco pequeno",IF(K47<10,"Risco moderado",IF(K47<28,"Risco alto","Risco crítico"))) -> Risco pequeno
E48: 8 | K48: =I48*J48 -> 0 | L48: =IF(K48<5,"Risco pequeno",IF(K48<10,"Risco moderado",IF(K48<28,"Risco alto","Risco crítico"))) -> Risco pequeno
E49: 9 | K49: =I49*J49 -> 0 | L49: =IF(K49<5,"Risco pequeno",IF(K49<10,"Risco moderado",IF(K49<28,"Risco alto","Risco crítico"))) -> Risco pequeno
E50: 10 | K50: =I50*J50 -> 0 | L50: =IF(K50<5,"Risco pequeno",IF(K50<10,"Risco moderado",IF(K50<28,"Risco alto","Risco crítico"))) -> Risco pequeno

Sheet Estrutura de quebra de trabalho
B9: Gerente do portfólio: | C9: ='Identificação do projeto'!C9 -> Coronel BM Moisés Magalhães de Sousa | H9: Programa: | I9: ='Identificação do projeto'!J9 -> Aperfeiçoamento Tecnológico do CBMMG
B10: Eixo: | C10: ='Identificação do projeto'!C10 -> Inovação e Transformação Digital | H10: Projeto: | I10: ='Identificação do projeto'!J10 -> Modernização dos Sistema de Informação do CBMMG - GT's Integrados
H11: Subprojeto: | I11: ='Identificação do projeto'!J11 -> Base Integrada de Segurança Pública - BISP
B12: Gerente de Eixo: | C12: ='Identificação do projeto'!C12 -> Coronel BM Luiz Frederico Barreto Pascoal | H12: Gerente de Projeto: | I12: ='Identificação do projeto'!J12 -> Tenente-coronel BM Paulo Afonso Montezano Crispim
E14: ESTRUTURA ANALÍTICA DO PROJETO (Estrutura de quebra de trabalho do projeto)

Sheet Entregas e custos previstos
B9: Gerente do portfólio: | C9: ='Identificação do projeto'!C9 -> Coronel BM Moisés Magalhães de Sousa | H9: Programa: | I9: ='Identificação do projeto'!J9 -> Aperfeiçoamento Tecnológico do CBMMG
B10: Eixo: | C10: ='Identificação do projeto'!C10 -> Inovação e Transformação Digital | H10: Projeto: | I10: ='Identificação do projeto'!J10 -> Modernização dos Sistema de Informação do CBMMG - GT's Integrados
H11: Subprojeto: | I11: ='Identificação do projeto'!J11 -> Base Integrada de Segurança Pública - BISP
B12: Gerente de Eixo: | C12: ='Identificação do projeto'!C12 -> Coronel BM Luiz Frederico Barreto Pascoal | H12: Gerente de Projeto: | I12: ='Identificação do projeto'!J12 -> Tenente-coronel BM Paulo Afonso Montezano Crispim
B15: Entregas previstas: | I15: Custos
B16: Principal Entrega | I16: Status de custo | J16: Custos do Projeto (R$) | K16: Observações (fonte e finalidade)
B17: Base Integrada de Segurança Pública (BISP) com os dados estratégicos do CBMMG integrados e disponíveis para inteligência de dados — com destaque para a integração dos dados de Recursos Humanos (SIGP), 17 universos, e respectivas views. | I17: NÃO CAPTADO | K17: Ferramenta DVM (IBM) para leitura direta do Mainframe. Aquisição prevista para mar/2026 via SEJUSP; verificar rateio ao CBMMG no contrato geral. Valor ainda não definido.
B18: Entrega(s) complementar(es) | I18: SEM ORÇAMENTO | J18: 0 | K18: Mão de obra da equipe técnica do CBMMG e utilização de equipamentos/infraestrutura já disponíveis na corporação.
B19: Módulo de Fiscalização do Infoscip integrado à BISP, com views para a DAT e alimentação do parâmetro "F" do ISCIP (concluído).
B20: Integração dos dados de RH (SIGP) viabilizada por meio da ferramenta DVM (leitura direta do Mainframe). | I20: TOTAL | J20: =SUM(J17:J19) -> 0
B21: Acessos técnicos à BISP concedidos à equipe do CBMMG (certificados digitais e ferramentas de consulta).
B22: Painéis de monitoramento, indicadores e relatórios gerenciais a partir dos dados da BISP.
B23: Manutenção da série histórica do ISCIP.
B24: Inclusão de campo/label de data da última atualização dos dados.

Sheet Cronograma
B8: Gerente do portfólio: | C8: Coronel BM Moisés Magalhães de Sousa | H8: Programa: | I8: Aperfeiçoamento Tecnológico do CBMMG
B9: Eixo: | C9: Inovação e Transformação Digital | H9: Projeto: | I9: Modernização dos Sistema de Informação do CBMMG - GT's Integrados
H10: Subprojeto: | I10: ='Identificação do projeto'!J11 -> Base Integrada de Segurança Pública - BISP
B11: Gerente de Eixo: | C11: Coronel BM Luiz Frederico Barreto Pascoal | H11: Gerente de Projeto: | I11: Tenente-coronel BM Paulo Afonso Montezano Crispim
B15: Pacotes de Trabalho | D15: Previsão de conclusão | E15: Percentual correspondente do projeto | G15: Status | H15: Responsável (opcional) | I15: Observações
B16: Solicitação formal de inclusão do Infoscip Fiscalização e SIGP na BISP | D16: 45916 | E16: 0.02 | G16: Concluído | H16: SDTS | I16: E-mail de 16/09/2025 encaminhado à Gerência da BISP (Maj Rocha), após conversa com oficiais da DRH (Cel Rubens, Ten Fortes, Ten Luíza) e DAT (Cap Simon). Solicitou inclusão das tabelas do Infoscip Fiscalização nos mesmos moldes do Licenciamento, além de manifestar interesse na inclusão dos dados do SIGP.
B17: Integração do Módulo de Licenciamento do Infoscip à BISP | D17: 45930 | E17: 0.05 | G17: Concluído | H17: PRODEMGE / DAT | I17: Integração já disponível na base da BISP. Serviu de modelo para a integração subsequente do Módulo de Fiscalização.
B18: Planejamento e execução da ingestão do Infoscip Fiscalização — Sprint 56 | D18: 45968 | E18: 0.08 | G18: Concluído | H18: PRODEMGE | I18: Conforme e-mail de 08/10/2025 de Júlio César Álvares Maciel (PRODEMGE/BISP): ingestão do Módulo de Fiscalização incluída na Sprint 56, previsão de entrega 07/11/2025. Quanto ao SIGP, informou que ainda estavam verificando junto ao time do SIGP. A integração foi concluída com sucesso e as views para a DAT foram criadas. Parâmetro "F" do ISCIP passa a ser alimentado exclusivamente por este módulo.
B19: Verificação da suspensão da integração de dados de RH pela DRH/SEJUSP | D19: 45996 | E19: 0.02 | G19: Concluído | H19: SDTS | I19: 05/12/2025 — Maj Rocha: Segundo informações da SEJUSP, a implantação dos dados de RH foi suspensa a pedido da DRH por estarem desenvolvendo novas funcionalidades no SIGP. A SDTS discordou da paralisação, entendendo não haver empecilho. Posição: após novas funcionalidades, atualizar a BISP sem suspender o serviço.
B20: Contato com o novo Superintendente do Data Lake — Alexandre Diegues | D20: 46020 | E20: 0.02 | G20: Concluído | H20: SDTS | I20: 19/12/2025 — Levantou-se que o novo Superintendente do Data Lake BISP seria Alexandre Diegues. Contato prévio realizado e reunião agendada para 29/12/2025. 29/12/2025 — Contato realizado com Alexandre Diegues. Aguardando definição de melhor data para reunião e levantamento de requisitos.
B21: Reunião de avaliação dos dados de RH na BISP — proposta da ferramenta DVM (IBM) | D21: 46021 | E21: 0.03 | G21: Concluído | H21: SDTS / SEJUSP | I21: 30/12/2025 — Maj Rocha: Reunião para avaliação da utilização dos dados DRH na BISP. Houve sugestão de aguardar a contratação de nova ferramenta da IBM, denominada "DVM", que possibilitará a leitura direta dos dados do SIGP sem necessidade de importar via FTP. Previsão de aquisição: março/2026. Custo a ser atribuído ao CBMMG; verificar possibilidade de incluir no contrato geral.
B22: Recebimento do cronograma de reuniões SEJUSP (março/2026) | D22: 46097 | E22: 0.01 | G22: Concluído | H22: SDTS | I22: 16/03/2026 — Sra. Ana Wernek encaminhou cronograma das reuniões de março envolvendo as Forças de Segurança Pública, disponibilizado em planilha compartilhada no SharePoint. Abrange temas: REDS Mobile, BISP, Novo CAD, entre outros.
B23: Participação na Reunião da BISP — encaminhamentos estratégicos | D23: 46097 | E23: 0.03 | G23: Concluído | H23: SDTS / CINSP | I23: 16/03/2026 — Reunião da BISP. Encaminhamentos: • Ten Wallace e Sd Bianca sugeriram que BM3 e CEB participem das reuniões da BISP. • Apontada necessidade de label de data da última atualização dos dados. • Maj Fabiano (CINSP) indicou Cap Marco Antônio como referência no uso dos dados BISP no CBMMG. • Cap Cleyton parabenizou inserção dos dados do CAD na BISP — fundamental para painéis de monitoramento nas chuvas de Juiz de Fora. • Questionado andamento da inserção de dados de RH. Sr. Alexandre Dieguez esclareceu duas questões: (1) necessidade de reestruturação de dados de RH apontada pela PRODEMGE; (2) necessidade de aquisição de ferramentas auxiliares pela SEJUSP para recepção dos dados de RH da PMMG e do CBMMG. • Sra. Ana Wernek ressaltou importância de acompanhar cronograma de reuniões da SEJUSP.
B24: Solicitação de acesso à BISP ao EMBM/2 (Cap Cleyton e Maj Rocha) | D24: 46105 | E24: 0.02 | G24: Concluído | H24: SDTS | I24: 24/03/2026 — Cap Cleyton: Encaminhada ao EMBM/2 a solicitação de inserção dos nomes do Cap Cleyton e do Maj Rocha para concessão de acesso aos dados da BISP, com finalidade de viabilizar o desenvolvimento de novas ferramentas e análise da estrutura de dados.
B25: Autorização de acesso à BISP pelo EMBM/2 | D25: 46150 | E25: 0.02 | G25: Concluído | H25: EMBM/2 | I25: 08/05/2026 — Maj Rocha: Acesso à BISP autorizado.
B26: Recebimento de parâmetros, instalação de certificados e testes técnicos | D26: 46168 | E26: 0.05 | G26: Concluído | H26: SDTS | I26: 26/05/2026 — Cap Cleyton: Recebido via SEI Nº 1400.01.0016266/2026-06 o conjunto de parâmetros para acesso. Instalação de certificados digitais e ferramentas de leitura/consulta realizada. Fase de testes técnicos obteve êxito.
B27: Verificação das bases disponíveis na BISP e reforço da continuidade do projeto RH | D27: 46168 | E27: 0.03 | G27: Concluído | H27: SDTS | I27: 26/05/2026 — Cap Cleyton: Constatou-se que existem na BISP, relacionadas ao CBMMG: Banco de dados do CAD; Banco de dados do CAD ESCALA (AAS); Banco de dados do REDS. Dados de RH não disponíveis — projeto paralisado. Reforçada junto à Sra. Ana Wernek a importância da continuidade da inserção dos dados de RH.
... B33: Manutenção da série histórica do ISCIP — parâmetro "F" via Infoscip Fiscalização | D33: 46568 | E33: 0.05 | G33: Em andamento | H33: DAT / SDTS | I33: O parâmetro "F" do ISCIP, antes extraído do REDS, passou a ser obtido exclusivamente do Infoscip Fiscalização (integrado na Sprint 56). Acompanhamento contínuo para garantir a continuidade e confiabilidade da série histórica do índice institucional.

Sheet Monitoramento
B9: Gerente do portfólio: | C9: Coronel BM Moisés Magalhães de Sousa | H9: Programa: | I9: Aperfeiçoamento Tecnológico do CBMMG
B10: Eixo: | C10: Inovação e Transformação Digital | H10: Projeto: | I10: Modernização dos Sistema de Informação do CBMMG - GT's Integrados
H11: Subprojeto: | I11: ='Identificação do projeto'!J11 -> Base Integrada de Segurança Pública - BISP
B12: Gerente de Eixo: | C12: Coronel BM Luiz Frederico Barreto Pascoal | H12: Gerente de Projeto: | I12: Tenente-coronel BM Paulo Afonso Montezano Crispim
B14: Situação atual do projeto | H14: Progresso do projeto (% concluído)
T16: =H16
T17: =I16
I18: Percentual previsto em | J18: =TODAY() -> 46237 | K18: 0.55 | M18: Indicador de evolução do projeto: | P18: =K19/K18 -> #NUM! | T18: =J16
I19: Percentual concluído até | J19: =TODAY() -> 46237 | K19: =LARGE(H16:O16,1) -> #NUM! | T19: =K16
M20: (relação entre o concluído e o previsto) | T20: =L16
B21: Atas reuniões de monitoramento | T21: =M16
B22: 1ª Reunião | T22: =N16
T23: =O16
B27: 2ª Reunião
B32: 3ª reunião
B37: 4ª Reunião
B42: 5ª Reunião
B47: 6ª reunião
B52: 7ª reunião
B57: 8ª reunião
B62: 9ª reunião
B67: 10ª reunião
B72: 11ª reunião
B77: 12ª reunião

Sheet Termo de Encerramento
A8: Gerente do portfólio: | B8: ='Identificação do projeto'!C9 -> Coronel BM Moisés Magalhães de Sousa | G8: Programa: | H8: ='Identificação do projeto'!J9 -> Aperfeiçoamento Tecnológico do CBMMG
A9: Eixo: | B9: ='Identificação do projeto'!C10 -> Inovação e Transformação Digital | G9: Projeto: | H9: ='Identificação do projeto'!J10 -> Modernização dos Sistema de Informação do CBMMG - GT's Integrados
G10: Subprojeto: | H10: ='Identificação do projeto'!J11 -> Base Integrada de Segurança Pública - BISP
A11: Gerente de Eixo: | B11: ='Identificação do projeto'!C12 -> Coronel BM Luiz Frederico Barreto Pascoal | G11: Gerente de Projeto: | H11: ='Identificação do projeto'!J12 -> Tenente-coronel BM Paulo Afonso Montezano Crispim
A13: OBJETIVO DO PROJETO (Puxado automaticamente da aba Identificação do projeto)
A14: ='Identificação do projeto'!A16 -> SITUAÇÃO ATUAL A Base Integrada de Segurança Pública (BISP) é o data lake corporativo dos sistemas das Forças de Segurança Pública (SISP), operado pela SEJUSP por meio da PRODEMGE. O CBMMG já possui integrados à BISP os dados do CAD, do CAD ESCALA (ainda utilizado pela AAS), do REDS e do Módulo de Licenciamento do Infoscip. O Módulo de Fiscalização do Infoscip foi integrado na Sprint 56 (entrega em 07/11/2025), com criação das views para a DAT. A etapa seguinte — inclusão dos dados de Recursos Humanos (SIGP), abrangendo os 17 universos de RH — encontra-se paralisada por depender da aquisição de ferramenta de terceiros (IBM "DVM") capaz de ler os dados diretamente do Mainframe, sem importação via FTP, com previsão de aquisição para março/2026 e possível custo a ser rateado ao CBMMG. STAKEHOLDERS Internos: SDTS, DAT, DRH, CINSP, EMBM/2 e AAS. Externos: SEJUSP (Observatório / Superintendência de Integração da Segurança Pública), PRODEMGE, PMMG e PCMG. JUSTIFICATIVA A consolidação dos dados do CBMMG em ambiente corporativo e seguro viabiliza o uso de inteligência de dados (painéis, indicadores e relatórios) e a tomada de decisão baseada em evidências. A integração do Infoscip Fiscalização é condição indispensável para a manutenção da série histórica do ISCIP, cujo parâmetro "F" passa a ser obtido exclusivamente desse módulo (antes oriundo do REDS). A integração dos dados de RH proporcionará salto qualitativo na gestão de pessoal (dimensionamento de efetivo, saúde ocupacional, controle de licenças e análises preditivas de disponibilidade). O acesso à BISP também permite ao CBMMG desenvolver ferramentas secundárias — como os painéis de monitoramento utilizados no período de fortes chuvas em Juiz de Fora —, agregando eficiência, economicidade e transparência ao serviço prestado à sociedade mineira.
A17: METAS E ENTREGAS PREVISTAS (Puxado automaticamente da aba Metas e entregas previstas)
A18: ='Entregas e custos previstos'!B16 -> Principal Entrega
A19: ='Entregas e custos previstos'!B17 -> Base Integrada de Segurança Pública (BISP) com os dados estratégicos do CBMMG integrados e disponíveis para inteligência de dados — com destaque para a integração dos dados de Recursos Humanos (SIGP), 17 universos, e respectivas views.
A20: ='Entregas e custos previstos'!B18 -> Entrega(s) complementar(es)
A21: ='Entregas e custos previstos'!B19 -> Módulo de Fiscalização do Infoscip integrado à BISP, com views para a DAT e alimentação do parâmetro "F" do ISCIP (concluído).
A22: ='Entregas e custos previstos'!B20 -> Integração dos dados de RH (SIGP) viabilizada por meio da ferramenta DVM (leitura direta do Mainframe).
A23: ='Entregas e custos previstos'!B21 -> Acessos técnicos à BISP concedidos à equipe do CBMMG (certificados digitais e ferramentas de consulta).
A24: ='Entregas e custos previstos'!B22 -> Painéis de monitoramento, indicadores e relatórios gerenciais a partir dos dados da BISP.
A25: ='Entregas e custos previstos'!B23 -> Manutenção da série histórica do ISCIP.
A26: ='Entregas e custos previstos'!B24 -> Inclusão de campo/label de data da última atualização dos dados.
A27: ='Entregas e custos previstos'!B25
A28: ='Entregas e custos previstos'!B26
A29: ADAPTAÇÕES NO ESCOPO INICIAL DO PROJETO
A30: "Caso tenha havido mudança no escopo inicial do projeto, inserir as informações neste campo, com as justificativas para alteração do escopo."
A33: STATUS DO PROJETO
B34: Observação: "Opcional"
A38: PRODUTOS
A39: PRINCIPAL ENTREGA
A40: Principal Entrega do Projeto | D40: ='Entregas e custos previstos'!B17 -> Base Integrada de Segurança Pública (BISP) com os dados estratégicos do CBMMG integrados e disponíveis para inteligência de dados — com destaque para a integração dos dados de Recursos Humanos (SIGP), 17 universos, e respectivas views.
A41: Documentos Comprobatórios
A43: ENTREGAS COMPLEMENTARES
A44: Produto | F44: Documentos Comprobatórios
A45: ='Entregas e custos previstos'!B20 -> Integração dos dados de RH (SIGP) viabilizada por meio da ferramenta DVM (leitura direta do Mainframe).
A46: ='Entregas e custos previstos'!B21 -> Acessos técnicos à BISP concedidos à equipe do CBMMG (certificados digitais e ferramentas de consulta).
A47: ='Entregas e custos previstos'!B22 -> Painéis de monitoramento, indicadores e relatórios gerenciais a partir dos dados da BISP.
A48: ='Entregas e custos previstos'!B23 -> Manutenção da série histórica do ISCIP.
A49: ='Entregas e custos previstos'!B24 -> Inclusão de campo/label de data da última atualização dos dados.
A50: ='Entregas e custos previstos'!B25
A51: ='Entregas e custos previstos'!B26
A52: ='Entregas e custos previstos'!B27
A53: ='Entregas e custos previstos'!B28
A54: ='Entregas e custos previstos'!B29
A56: PRINCIPAIS PROBLEMAS E ENTRAVES
A57: Problemas durante a execução do projeto | F57: Impacto no desenvolvimento
...
